Workbook
Name IQ_CH: 110000
Name IQ_CQ: 5000
Name IQ_CY: 10000
Name IQ_DAILY: 500000
Name IQ_FH: 100000
Name IQ_FQ: 500
Name IQ_FY: 1000
Name IQ_LTM: 2000
Name IQ_MONTH: 15000
Name IQ_NTM: 6000
Name IQ_WEEK: 50000
Name IQ_YTD: 3000
Name UPDATE: 'Data Sheet'!$E$1

Sheet HistoricalFS
B2: ="Historical Financial Statement - "&'Data Sheet'!B1 -> Historical Financial Statement - MAX HEALTHCARE INSTITUTE LTD
B3: Years | C3: ='Data Sheet'!B16 -> 41729 | D3: ='Data Sheet'!C16 -> 42825 | E3: ='Data Sheet'!D16 -> 43190 | F3: ='Data Sheet'!E16 -> 43555 | G3: ='Data Sheet'!F16 -> 43921 | H3: ='Data Sheet'!G16 -> 44286 | I3: ='Data Sheet'!H16 -> 44651 | J3: ='Data Sheet'!I16 -> 45016 | ... L3: ='Data Sheet'!K16 -> 45747 | M3: LTM
A5: # | B5: Income Statement
B6: Sales | C6: =IFERROR('Data Sheet'!B17,0) -> 0 | D6: =IFERROR('Data Sheet'!C17,0) -> 1608.26 | E6: =IFERROR('Data Sheet'!D17,0) -> 1729.13 | F6: =IFERROR('Data Sheet'!E17,0) -> 1691.02 | G6: =IFERROR('Data Sheet'!F17,0) -> 1059.03 | H6: =IFERROR('Data Sheet'!G17,0) -> 2504.67 | I6: =IFERROR('Data Sheet'!H17,0) -> 3931.46 | J6: =IFERROR('Data Sheet'!I17,0) -> 4562.6 | ... L6: =IFERROR('Data Sheet'!K17,0) -> 7028.46 | M6: =IFERROR(SUM('Data Sheet'!H42:K42),0) -> 7941.09
B7: Sales Growth | C7: - | D7: =D6/C6-1 -> #DIV/0! | E7: =E6/D6-1 -> 0.075155758 | F7: =F6/E6-1 -> -0.022039985 | G7: =G6/F6-1 -> -0.37373301 | H7: =H6/G6-1 -> 1.3650605 | I7: =I6/H6-1 -> 0.56965189 | J7: =J6/I6-1 -> 0.16053578 | K7: =K6/J6-1 -> 0.18485513 | ... M7: =M6/L6-1 -> 0.12984779
B9: COGS | C9: =IFERROR(SUM('Data Sheet'!B18,'Data Sheet'!B20:B22)-1*'Data Sheet'!B19,0) -> 0 | D9: =IFERROR(SUM('Data Sheet'!C18,'Data Sheet'!C20:C22)-1*'Data Sheet'!C19,0) -> 853.13 | E9: =IFERROR(SUM('Data Sheet'!D18,'Data Sheet'!D20:D22)-1*'Data Sheet'!D19,0) -> 950.67 | F9: =IFERROR(SUM('Data Sheet'!E18,'Data Sheet'!E20:E22)-1*'Data Sheet'!E19,0) -> 889.55 | G9: =IFERROR(SUM('Data Sheet'!F18,'Data Sheet'!F20:F22)-1*'Data Sheet'!F19,0) -> 777.72 | H9: =IFERROR(SUM('Data Sheet'!G18,'Data Sheet'!G20:G22)-1*'Data Sheet'!G19,0) -> 1853.2 | I9: =IFERROR(SUM('Data Sheet'!H18,'Data Sheet'!H20:H22)-1*'Data Sheet'!H19,0) -> 2675.78 | J9: =IFERROR(SUM('Data Sheet'!I18,'Data Sheet'!I20:I22)-1*'Data Sheet'!I19,0) -> 2924.59 | ... L9: =IFERROR(SUM('Data Sheet'!K18,'Data Sheet'!K20:K22)-1*'Data Sheet'!K19,0) -> 4473.09 | M9: =IFERROR(SUM('Data Sheet'!H43:K43),0) -> 5832.28
B10: COGS % Sales | C10: =C9/C6 -> #DIV/0! | D10: =D9/D6 -> 0.53046771 | E10: =E9/E6 -> 0.54979672 | F10: =F9/F6 -> 0.52604345 | G10: =G9/G6 -> 0.73437013 | H10: =H9/H6 -> 0.73989787 | I10: =I9/I6 -> 0.6806072 | J10: =J9/J6 -> 0.64099198 | ... M10: =M9/M6 -> 0.73444326
B12: Gross Profit | C12: =C6-C9 -> 0 | D12: =D6-D9 -> 755.13 | E12: =E6-E9 -> 778.46 | F12: =F6-F9 -> 801.47 | G12: =G6-G9 -> 281.31 | H12: =H6-H9 -> 651.47 | I12: =I6-I9 -> 1255.68 | J12: =J6-J9 -> 1638.01 | ... M12: =M6-M9 -> 2108.81
B13: Gross Margins | C13: =C12/C6 -> #DIV/0! | D13: =D12/D6 -> 0.46953229 | E13: =E12/E6 -> 0.45020328 | F13: =F12/F6 -> 0.47395655 | G13: =G12/G6 -> 0.26562987 | H13: =H12/H6 -> 0.26010213 | I13: =I12/I6 -> 0.3193928 | J13: =J12/J6 -> 0.35900802 | ... M13: =M12/M6 -> 0.26555674
B15: Selling & General Expenses | C15: =IFERROR(SUM('Data Sheet'!B23:B24),0) -> 0 | D15: =IFERROR(SUM('Data Sheet'!C23:C24),0) -> 614.21 | E15: =IFERROR(SUM('Data Sheet'!D23:D24),0) -> 665.06 | F15: =IFERROR(SUM('Data Sheet'!E23:E24),0) -> 645.41 | G15: =IFERROR(SUM('Data Sheet'!F23:F24),0) -> 187.66 | H15: =IFERROR(SUM('Data Sheet'!G23:G24),0) -> 247.37 | I15: =IFERROR(SUM('Data Sheet'!H23:H24),0) -> 310.06 | J15: =IFERROR(SUM('Data Sheet'!I23:I24),0) -> 397.48 | ... L15: =IFERROR(SUM('Data Sheet'!K23:K24),0) -> 706.57
B16: S&G Exp % Sales | C16: =C15/C6 -> #DIV/0! | D16: =D15/D6 -> 0.38190964 | E16: =E15/E6 -> 0.38462117 | F16: =F15/F6 -> 0.38166905 | G16: =G15/G6 -> 0.17719989 | H16: =H15/H6 -> 0.09876351 | I16: =I15/I6 -> 0.078866375 | J16: =J15/J6 -> 0.087116995 | ... M16: =M15/M6 -> 0
B18: EBITDA | C18: =C12-C15 -> 0 | D18: =D12-D15 -> 140.92 | E18: =E12-E15 -> 113.4 | F18: =F12-F15 -> 156.06 | G18: =G12-G15 -> 93.65 | H18: =H12-H15 -> 404.1 | I18: =I12-I15 -> 945.62 | J18: =J12-J15 -> 1240.53 | ... L18: =L12-L15 -> 1848.8 | M18: =IFERROR(SUM('Data Sheet'!H51:K51),0) -> 2184.81
B19: EBITDA Margins | C19: =C18/C6 -> #DIV/0! | D19: =D18/D6 -> 0.087622648 | E19: =E18/E6 -> 0.065582114 | F19: =F18/F6 -> 0.092287495 | G19: =G18/G6 -> 0.088429978 | H19: =H18/H6 -> 0.16133862 | I19: =I18/I6 -> 0.24052642 | J19: =J18/J6 -> 0.27189103 | ... M19: =M18/M6 -> 0.27512722
B21: Interest | C21: =IFERROR('Data Sheet'!B27,0) -> 0 | D21: =IFERROR('Data Sheet'!C27,0) -> 99.68 | E21: =IFERROR('Data Sheet'!D27,0) -> 99.37 | F21: =IFERROR('Data Sheet'!E27,0) -> 101.27 | G21: =IFERROR('Data Sheet'!F27,0) -> 83.24 | H21: =IFERROR('Data Sheet'!G27,0) -> 179.46 | I21: =IFERROR('Data Sheet'!H27,0) -> 100.87 | J21: =IFERROR('Data Sheet'!I27,0) -> 83.86 | ... L21: =IFERROR('Data Sheet'!K27,0) -> 165.02 | M21: =IFERROR(SUM('Data Sheet'!H46:K46),0) -> 216.37
B22: Interest % Sales | C22: =C21/C6 -> #DIV/0! | D22: =D21/D6 -> 0.061980028 | E22: =E21/E6 -> 0.057468207 | F22: =F21/F6 -> 0.059886932 | G22: =G21/G6 -> 0.078600229 | H22: =H21/H6 -> 0.071650158 | I22: =I21/I6 -> 0.025657135 | J22: =J21/J6 -> 0.018379871 | ... M22: =M21/M6 -> 0.027246889
B24: Depreciation | C24: =IFERROR('Data Sheet'!B26,0) -> 0 | D24: =IFERROR('Data Sheet'!C26,0) -> 95.51 | E24: =IFERROR('Data Sheet'!D26,0) -> 94.42 | F24: =IFERROR('Data Sheet'!E26,0) -> 102.64 | G24: =IFERROR('Data Sheet'!F26,0) -> 45.64 | H24: =IFERROR('Data Sheet'!G26,0) -> 174.09 | I24: =IFERROR('Data Sheet'!H26,0) -> 221.12 | J24: =IFERROR('Data Sheet'!I26,0) -> 232.19 | ... L24: =IFERROR('Data Sheet'!K26,0) -> 359.42 | M24: =IFERROR(SUM('Data Sheet'!H45:K45),0) -> 410.61
B25: Depreciation%Sales | C25: =C24/C6 -> #DIV/0! | D25: =D24/D6 -> 0.059387164 | E25: =E24/E6 -> 0.054605495 | F25: =F24/F6 -> 0.060697094 | G25: =G24/G6 -> 0.043096041 | H25: =H24/H6 -> 0.069506162 | I25: =I24/I6 -> 0.056243736 | J25: =J24/J6 -> 0.050889844 | ... M25: =M24/M6 -> 0.051707007
B27: Earnings Before Tax | C27: =IFERROR(C18-SUM(C24,C21),0) -> 0 | D27: =IFERROR(D18-SUM(D24,D21),0) -> -54.27 | E27: =IFERROR(E18-SUM(E24,E21),0) -> -80.39 | F27: =IFERROR(F18-SUM(F24,F21),0) -> -47.85 | G27: =IFERROR(G18-SUM(G24,G21),0) -> -35.23 | H27: =IFERROR(H18-SUM(H24,H21),0) -> 50.55 | I27: =IFERROR(I18-SUM(I24,I21),0) -> 623.63 | J27: =IFERROR(J18-SUM(J24,J21),0) -> 924.48 | ... M27: =IFERROR(M18-SUM(M24,M21),0) -> 1557.83
B28: EBT % Sales | C28: =C27/C6 -> #DIV/0! | D28: =D27/D6 -> -0.033744544 | E28: =E27/E6 -> -0.046491588 | F28: =F27/F6 -> -0.028296531 | G28: =G27/G6 -> -0.033266291 | H28: =H27/H6 -> 0.020182299 | I28: =I27/I6 -> 0.15862555 | J28: =J27/J6 -> 0.20262131 | ... M28: =M27/M6 -> 0.19617332
B30: Tax | C30: =IFERROR('Data Sheet'!B29,0) -> 0 | D30: =IFERROR('Data Sheet'!C29,0) -> -11.09 | E30: =IFERROR('Data Sheet'!D29,0) -> 9.95 | F30: =IFERROR('Data Sheet'!E29,0) -> 8.51 | G30: =IFERROR('Data Sheet'!F29,0) -> -0.13 | H30: =IFERROR('Data Sheet'!G29,0) -> 45.85 | I30: =IFERROR('Data Sheet'!H29,0) -> 133.85 | J30: =IFERROR('Data Sheet'!I29,0) -> -39.79 | ... L30: =IFERROR('Data Sheet'!K29,0) -> 330.49 | M30: =IFERROR(SUM('Data Sheet'!H48:K48),0) -> 200.76
B31: Effective Tax Rate | C31: =C30/C27 -> #DIV/0! | D31: =D30/D27 -> 0.20434863 | E31: =E30/E27 -> -0.12377161 | F31: =F30/F27 -> -0.17784744 | G31: =G30/G27 -> 0.0036900369 | H31: =H30/H27 -> 0.90702275 | I31: =I30/I27 -> 0.21463047 | J31: =J30/J27 -> -0.043040412 | ... M31: =M30/M27 -> 0.12887157
B33: Net Profit | C33: =IFERROR(C27-C30,0) -> 0 | D33: =IFERROR(D27-D30,0) -> -43.18 | E33: =IFERROR(E27-E30,0) -> -90.34 | F33: =IFERROR(F27-F30,0) -> -56.36 | G33: =IFERROR(G27-G30,0) -> -35.1 | H33: =IFERROR(H27-H30,0) -> 4.7 | I33: =IFERROR(I27-I30,0) -> 489.78 | J33: =IFERROR(J27-J30,0) -> 964.27 | ... M33: =IFERROR(M27-M30,0) -> 1357.07
B34: Net Margins | C34: =C33/C6 -> #DIV/0! | D34: =D33/D6 -> -0.026848893 | E34: =E33/E6 -> -0.052245927 | F34: =F33/F6 -> -0.033328997 | G34: =G33/G6 -> -0.033143537 | H34: =H33/H6 -> 0.0018764947 | I34: =I33/I6 -> 0.12457967 | J34: =J33/J6 -> 0.21134222 | ... M34: =M33/M6 -> 0.17089216
B36: No of Equity Shares | C36: =IFERROR('Data Sheet'!B93,0) -> 0 | D36: =IFERROR('Data Sheet'!C93,0) -> 53.72 | E36: =IFERROR('Data Sheet'!D93,0) -> 53.72 | F36: =IFERROR('Data Sheet'!E93,0) -> 53.72 | G36: =IFERROR('Data Sheet'!F93,0) -> 53.72 | H36: =IFERROR('Data Sheet'!G93,0) -> 96.59 | I36: =IFERROR('Data Sheet'!H93,0) -> 96.96 | J36: =IFERROR('Data Sheet'!I93,0) -> 97.09 | ... L36: =IFERROR('Data Sheet'!K93,0) -> 97.21 | M36: =L36 -> 97.21
B38: Earnings per Share | C38: =IFERROR(C33/C36,0) -> 0 | D38: =IFERROR(D33/D36,0) -> -0.80379747 | E38: =IFERROR(E33/E36,0) -> -1.6816828 | F38: =IFERROR(F33/F36,0) -> -1.0491437 | G38: =IFERROR(G33/G36,0) -> -0.65338794 | H38: =IFERROR(H33/H36,0) -> 0.048659281 | I38: =IFERROR(I33/I36,0) -> 5.0513614 | J38: =IFERROR(J33/J36,0) -> 9.9317128 | ... M38: =IFERROR(M33/M36,0) -> 13.960189
B39: EPS Growth % | D39: =IFERROR(D38/C38-1,0) -> 0 | E39: =IFERROR(E38/D38-1,0) -> 1.0921723 | F39: =IFERROR(F38/E38-1,0) -> -0.3761346 | G39: =IFERROR(G38/F38-1,0) -> -0.37721789 | H39: =IFERROR(H38/G38-1,0) -> -1.0744723 | I39: =IFERROR(I38/H38-1,0) -> 102.81085 | J39: =IFERROR(J38/I38-1,0) -> 0.96614577 | K39: =IFERROR(K38/J38-1,0) -> -0.088777003 | ... M39: =IFERROR(M38/L38-1,0) -> 0.36544015
B41: Dividend per Share | C41: =IFERROR('Data Sheet'!B31/HistoricalFS!C36,0) -> 0 | D41: =IFERROR('Data Sheet'!C31/HistoricalFS!D36,0) -> 0 | E41: =IFERROR('Data Sheet'!D31/HistoricalFS!E36,0) -> 0 | F41: =IFERROR('Data Sheet'!E31/HistoricalFS!F36,0) -> 0 | G41: =IFERROR('Data Sheet'!F31/HistoricalFS!G36,0) -> 0 | H41: =IFERROR('Data Sheet'!G31/HistoricalFS!H36,0) -> 0 | I41: =IFERROR('Data Sheet'!H31/HistoricalFS!I36,0) -> 0 | J41: =IFERROR('Data Sheet'!I31/HistoricalFS!J36,0) -> 1 | ... M41: =IFERROR('Data Sheet'!L31/HistoricalFS!M36,0) -> 0
B42: Dividend payout ratio | C42: =IFERROR(C41/C38,0) -> 0 | D42: =IFERROR(D41/D38,0) -> 0 | E42: =IFERROR(E41/E38,0) -> 0 | F42: =IFERROR(F41/F38,0) -> 0 | G42: =IFERROR(G41/G38,0) -> 0 | H42: =IFERROR(H41/H38,0) -> 0 | I42: =IFERROR(I41/I38,0) -> 0 | J42: =IFERROR(J41/J38,0) -> 0.10068757 | ... M42: =IFERROR(M41/M38,0) -> 0
B44: Retained Earnings | C44: =IFERROR(IF(C38>C41,1-C42,0),0) -> 0 | D44: =IFERROR(IF(D38>D41,1-D42,0),0) -> 0 | E44: =IFERROR(IF(E38>E41,1-E42,0),0) -> 0 | F44: =IFERROR(IF(F38>F41,1-F42,0),0) -> 0 | G44: =IFERROR(IF(G38>G41,1-G42,0),0) -> 0 | H44: =IFERROR(IF(H38>H41,1-H42,0),0) -> 1 | I44: =IFERROR(IF(I38>I41,1-I42,0),0) -> 1 | J44: =IFERROR(IF(J38>J41,1-J42,0),0) -> 0.89931243 | ... M44: =IFERROR(IF(M38>M41,1-M42,0),0) -> 1
A46: # | B46: Balance Sheet
B47: Equity Share Capital | C47: =IFERROR('Data Sheet'!B57,0) -> 0 | D47: =IFERROR('Data Sheet'!C57,0) -> 537.24 | E47: =IFERROR('Data Sheet'!D57,0) -> 537.24 | F47: =IFERROR('Data Sheet'!E57,0) -> 537.24 | G47: =IFERROR('Data Sheet'!F57,0) -> 537.24 | H47: =IFERROR('Data Sheet'!G57,0) -> 965.95 | I47: =IFERROR('Data Sheet'!H57,0) -> 969.61 | J47: =IFERROR('Data Sheet'!I57,0) -> 970.92 | ... L47: =IFERROR('Data Sheet'!K57,0) -> 972.14
B48: Reserves | C48: =IFERROR('Data Sheet'!B58,0) -> 0 | D48: =IFERROR('Data Sheet'!C58,0) -> 655.14 | E48: =IFERROR('Data Sheet'!D58,0) -> 626.67 | F48: =IFERROR('Data Sheet'!E58,0) -> 425.95 | G48: =IFERROR('Data Sheet'!F58,0) -> 2015.91 | H48: =IFERROR('Data Sheet'!G58,0) -> 4672.73 | I48: =IFERROR('Data Sheet'!H58,0) -> 5312.86 | J48: =IFERROR('Data Sheet'!I58,0) -> 6438.67 | ... L48: =IFERROR('Data Sheet'!K58,0) -> 8408.73
B49: Borrowings | C49: =IFERROR('Data Sheet'!B59,0) -> 0 | D49: =IFERROR('Data Sheet'!C59,0) -> 874.09 | E49: =IFERROR('Data Sheet'!D59,0) -> 980.52 | F49: =IFERROR('Data Sheet'!E59,0) -> 1002.75 | G49: =IFERROR('Data Sheet'!F59,0) -> 874.74 | H49: =IFERROR('Data Sheet'!G59,0) -> 1101.41 | I49: =IFERROR('Data Sheet'!H59,0) -> 913.38 | J49: =IFERROR('Data Sheet'!I59,0) -> 688.96 | ... L49: =IFERROR('Data Sheet'!K59,0) -> 3010.29
B50: Other Liabilities | C50: =IFERROR('Data Sheet'!B60,0) -> 0 | D50: =IFERROR('Data Sheet'!C60,0) -> 1079.63 | E50: =IFERROR('Data Sheet'!D60,0) -> 1157.09 | F50: =IFERROR('Data Sheet'!E60,0) -> 1388.6 | G50: =IFERROR('Data Sheet'!F60,0) -> 545.77 | H50: =IFERROR('Data Sheet'!G60,0) -> 1803.37 | I50: =IFERROR('Data Sheet'!H60,0) -> 1993.28 | J50: =IFERROR('Data Sheet'!I60,0) -> 2003.3 | ... L50: =IFERROR('Data Sheet'!K60,0) -> 2795.28
B51: Total Liabilities | C51: =IFERROR('Data Sheet'!B61,0) -> 0 | D51: =IFERROR('Data Sheet'!C61,0) -> 3146.1 | E51: =IFERROR('Data Sheet'!D61,0) -> 3301.52 | F51: =IFERROR('Data Sheet'!E61,0) -> 3354.54 | G51: =IFERROR('Data Sheet'!F61,0) -> 3973.66 | H51: =IFERROR('Data Sheet'!G61,0) -> 8543.46 | I51: =IFERROR('Data Sheet'!H61,0) -> 9189.13 | J51: =IFERROR('Data Sheet'!I61,0) -> 10101.85 | ... L51: =IFERROR('Data Sheet'!K61,0) -> 15186.44
B53: Fixed Assets Net Block | C53: =IFERROR('Data Sheet'!B62,0) -> 0 | D53: =IFERROR('Data Sheet'!C62,0) -> 2244.24 | E53: =IFERROR('Data Sheet'!D62,0) -> 2227.18 | F53: =IFERROR('Data Sheet'!E62,0) -> 2192.37 | G53: =IFERROR('Data Sheet'!F62,0) -> 850.95 | H53: =IFERROR('Data Sheet'!G62,0) -> 6536.38 | I53: =IFERROR('Data Sheet'!H62,0) -> 7017.58 | J53: =IFERROR('Data Sheet'!I62,0) -> 7038.7 | ... L53: =IFERROR('Data Sheet'!K62,0) -> 11501.59
B54: Capital Work in Progress | C54: =IFERROR('Data Sheet'!B63,0) -> 0 | D54: =IFERROR('Data Sheet'!C63,0) -> 46.14 | E54: =IFERROR('Data Sheet'!D63,0) -> 38.3 | F54: =IFERROR('Data Sheet'!E63,0) -> 87.02 | G54: =IFERROR('Data Sheet'!F63,0) -> 27.55 | H54: =IFERROR('Data Sheet'!G63,0) -> 26.93 | I54: =IFERROR('Data Sheet'!H63,0) -> 151.12 | J54: =IFERROR('Data Sheet'!I63,0) -> 252.43 | ... L54: =IFERROR('Data Sheet'!K63,0) -> 900.72
B55: Investments | C55: =IFERROR('Data Sheet'!B64,0) -> 0 | D55: =IFERROR('Data Sheet'!C64,0) -> 0 | E55: =IFERROR('Data Sheet'!D64,0) -> 0 | F55: =IFERROR('Data Sheet'!E64,0) -> 0.51 | G55: =IFERROR('Data Sheet'!F64,0) -> 2182.06 | H55: =IFERROR('Data Sheet'!G64,0) -> 0.51 | I55: =IFERROR('Data Sheet'!H64,0) -> 0.51 | J55: =IFERROR('Data Sheet'!I64,0) -> 0.51 | ... L55: =IFERROR('Data Sheet'!K64,0) -> 2.89
B56: Other Assets | C56: =IFERROR('Data Sheet'!B65-SUM('Data Sheet'!B67:B69),0) -> 0 | D56: =IFERROR('Data Sheet'!C65-SUM('Data Sheet'!C67:C69),0) -> 575.03 | E56: =IFERROR('Data Sheet'!D65-SUM('Data Sheet'!D67:D69),0) -> 638.24 | F56: =IFERROR('Data Sheet'!E65-SUM('Data Sheet'!E67:E69),0) -> 674.38 | G56: =IFERROR('Data Sheet'!F65-SUM('Data Sheet'!F67:F69),0) -> 670.64 | H56: =IFERROR('Data Sheet'!G65-SUM('Data Sheet'!G67:G69),0) -> 907.03 | I56: =IFERROR('Data Sheet'!H65-SUM('Data Sheet'!H67:H69),0) -> 1073.89 | J56: =IFERROR('Data Sheet'!I65-SUM('Data Sheet'!I67:I69),0) -> 929.79 | ... L56: =IFERROR('Data Sheet'!K65-SUM('Data Sheet'!K67:K69),0) -> 1305.83
B57: Total Non Current Assets | C57: =SUM(C53:C56) -> 0 | D57: =SUM(D53:D56) -> 2865.41 | E57: =SUM(E53:E56) -> 2903.72 | F57: =SUM(F53:F56) -> 2954.28 | G57: =SUM(G53:G56) -> 3731.2 | H57: =SUM(H53:H56) -> 7470.85 | I57: =SUM(I53:I56) -> 8243.1 | J57: =SUM(J53:J56) -> 8221.43 | ... L57: =SUM(L53:L56) -> 13711.03
...

Sheet Ratio Analysis
B2: ="Ratio Analysis of - "&'Data Sheet'!B1 -> Ratio Analysis of - MAX HEALTHCARE INSTITUTE LTD
B3: Years | C3: ='Data Sheet'!B16 -> 41729 | D3: ='Data Sheet'!C16 -> 42825 | E3: ='Data Sheet'!D16 -> 43190 | F3: ='Data Sheet'!E16 -> 43555 | G3: ='Data Sheet'!F16 -> 43921 | H3: ='Data Sheet'!G16 -> 44286 | I3: ='Data Sheet'!H16 -> 44651 | J3: ='Data Sheet'!I16 -> 45016 | ... L3: ='Data Sheet'!K16 -> 45747 | M3: Trend | N3: Mean | O3: Median
B5: SalesGrowth | D5: =IFERROR(HistoricalFS!D7,0) -> 0 | E5: =IFERROR(HistoricalFS!E7,0) -> 0.075155758 | F5: =IFERROR(HistoricalFS!F7,0) -> -0.022039985 | G5: =IFERROR(HistoricalFS!G7,0) -> -0.37373301 | H5: =IFERROR(HistoricalFS!H7,0) -> 1.3650605 | I5: =IFERROR(HistoricalFS!I7,0) -> 0.56965189 | J5: =IFERROR(HistoricalFS!J7,0) -> 0.16053578 | K5: =IFERROR(HistoricalFS!K7,0) -> 0.18485513 | L5: =IFERROR(HistoricalFS!L7,0) -> 0.30011728 | N5: =IFERROR(AVERAGE(D5:L5),0) -> 0.25106703 | O5: =IFERROR(MEDIAN(C5:L5),0) -> 0.16053578
B6: EBITDA Growth | D6: =IFERROR(HistoricalFS!D18/HistoricalFS!C18-1,0) -> 0 | E6: =IFERROR(HistoricalFS!E18/HistoricalFS!D18-1,0) -> -0.19528811 | F6: =IFERROR(HistoricalFS!F18/HistoricalFS!E18-1,0) -> 0.37619048 | G6: =IFERROR(HistoricalFS!G18/HistoricalFS!F18-1,0) -> -0.39991029 | H6: =IFERROR(HistoricalFS!H18/HistoricalFS!G18-1,0) -> 3.3150027 | I6: =IFERROR(HistoricalFS!I18/HistoricalFS!H18-1,0) -> 1.3400643 | J6: =IFERROR(HistoricalFS!J18/HistoricalFS!I18-1,0) -> 0.31186946 | K6: =IFERROR(HistoricalFS!K18/HistoricalFS!J18-1,0) -> 0.20280848 | L6: =IFERROR(HistoricalFS!L18/HistoricalFS!K18-1,0) -> 0.23904244 | N6: =IFERROR(AVERAGE(D6:L6),0) -> 0.57664216 | O6: =IFERROR(MEDIAN(C6:L6),0) -> 0.23904244
B7: EBIT Growth | D7: =IFERROR(HistoricalFS!D27/HistoricalFS!C27-1,0) -> 0 | E7: =IFERROR(HistoricalFS!E27/HistoricalFS!D27-1,0) -> 0.48129722 | F7: =IFERROR(HistoricalFS!F27/HistoricalFS!E27-1,0) -> -0.40477671 | G7: =IFERROR(HistoricalFS!G27/HistoricalFS!F27-1,0) -> -0.26374086 | H7: =IFERROR(HistoricalFS!H27/HistoricalFS!G27-1,0) -> -2.4348567 | I7: =IFERROR(HistoricalFS!I27/HistoricalFS!H27-1,0) -> 11.336894 | J7: =IFERROR(HistoricalFS!J27/HistoricalFS!I27-1,0) -> 0.48241746 | K7: =IFERROR(HistoricalFS!K27/HistoricalFS!J27-1,0) -> 0.28423546 | L7: =IFERROR(HistoricalFS!L27/HistoricalFS!K27-1,0) -> 0.11548537 | N7: =IFERROR(AVERAGE(D7:L7),0) -> 1.0663284 | O7: =IFERROR(MEDIAN(C7:L7),0) -> 0.11548537
B8: Net Profit Growth | D8: =IFERROR(HistoricalFS!D33/HistoricalFS!C33-1,0) -> 0 | E8: =IFERROR(HistoricalFS!E33/HistoricalFS!D33-1,0) -> 1.0921723 | F8: =IFERROR(HistoricalFS!F33/HistoricalFS!E33-1,0) -> -0.3761346 | G8: =IFERROR(HistoricalFS!G33/HistoricalFS!F33-1,0) -> -0.37721789 | H8: =IFERROR(HistoricalFS!H33/HistoricalFS!G33-1,0) -> -1.1339031 | I8: =IFERROR(HistoricalFS!I33/HistoricalFS!H33-1,0) -> 103.20851 | J8: =IFERROR(HistoricalFS!J33/HistoricalFS!I33-1,0) -> 0.9687819 | K8: =IFERROR(HistoricalFS!K33/HistoricalFS!J33-1,0) -> -0.087838468 | L8: =IFERROR(HistoricalFS!L33/HistoricalFS!K33-1,0) -> 0.12994986 | N8: =IFERROR(AVERAGE(D8:L8),0) -> 11.491591 | O8: =IFERROR(MEDIAN(C8:L8),0) -> 0
B9: Dividend Growth | D9: =IFERROR(HistoricalFS!D41/HistoricalFS!C41-1,0) -> 0 | E9: =IFERROR(HistoricalFS!E41/HistoricalFS!D41-1,0) -> 0 | F9: =IFERROR(HistoricalFS!F41/HistoricalFS!E41-1,0) -> 0 | G9: =IFERROR(HistoricalFS!G41/HistoricalFS!F41-1,0) -> 0 | H9: =IFERROR(HistoricalFS!H41/HistoricalFS!G41-1,0) -> 0 | I9: =IFERROR(HistoricalFS!I41/HistoricalFS!H41-1,0) -> 0 | J9: =IFERROR(HistoricalFS!J41/HistoricalFS!I41-1,0) -> 0 | K9: =IFERROR(HistoricalFS!K41/HistoricalFS!J41-1,0) -> 0.50005145 | L9: =IFERROR(HistoricalFS!L41/HistoricalFS!K41-1,0) -> -7.0560446e-09 | N9: =IFERROR(AVERAGE(D9:L9),0) -> 0.055561271 | O9: =IFERROR(MEDIAN(C9:L9),0) -> 0
B11: Gross Margin | C11: =IFERROR(HistoricalFS!C13,0) -> 0 | D11: =IFERROR(HistoricalFS!D13,0) -> 0.46953229 | E11: =IFERROR(HistoricalFS!E13,0) -> 0.45020328 | F11: =IFERROR(HistoricalFS!F13,0) -> 0.47395655 | G11: =IFERROR(HistoricalFS!G13,0) -> 0.26562987 | H11: =IFERROR(HistoricalFS!H13,0) -> 0.26010213 | I11: =IFERROR(HistoricalFS!I13,0) -> 0.3193928 | J11: =IFERROR(HistoricalFS!J13,0) -> 0.35900802 | ... L11: =IFERROR(HistoricalFS!L13,0) -> 0.36357467 | N11: =IFERROR(AVERAGE(C11:L11),0) -> 0.33309746 | O11: =IFERROR(MEDIAN(C11:L11),0) -> 0.36129134
B12: EBITDA Margin | C12: =IFERROR(HistoricalFS!C19,0) -> 0 | D12: =IFERROR(HistoricalFS!D19,0) -> 0.087622648 | E12: =IFERROR(HistoricalFS!E19,0) -> 0.065582114 | F12: =IFERROR(HistoricalFS!F19,0) -> 0.092287495 | G12: =IFERROR(HistoricalFS!G19,0) -> 0.088429978 | H12: =IFERROR(HistoricalFS!H19,0) -> 0.16133862 | I12: =IFERROR(HistoricalFS!I19,0) -> 0.24052642 | J12: =IFERROR(HistoricalFS!J19,0) -> 0.27189103 | ... L12: =IFERROR(HistoricalFS!L19,0) -> 0.26304482 | N12: =IFERROR(AVERAGE(C12:L12),0) -> 0.15467339 | O12: =IFERROR(MEDIAN(C12:L12),0) -> 0.12681306
B13: EBIT Margin | C13: =IFERROR((HistoricalFS!C18-HistoricalFS!C24)/HistoricalFS!C6,0) -> 0 | D13: =IFERROR((HistoricalFS!D18-HistoricalFS!D24)/HistoricalFS!D6,0) -> 0.028235484 | E13: =IFERROR((HistoricalFS!E18-HistoricalFS!E24)/HistoricalFS!E6,0) -> 0.010976618 | F13: =IFERROR((HistoricalFS!F18-HistoricalFS!F24)/HistoricalFS!F6,0) -> 0.031590401 | G13: =IFERROR((HistoricalFS!G18-HistoricalFS!G24)/HistoricalFS!G6,0) -> 0.045333938 | H13: =IFERROR((HistoricalFS!H18-HistoricalFS!H24)/HistoricalFS!H6,0) -> 0.091832457 | I13: =IFERROR((HistoricalFS!I18-HistoricalFS!I24)/HistoricalFS!I6,0) -> 0.18428268 | J13: =IFERROR((HistoricalFS!J18-HistoricalFS!J24)/HistoricalFS!J6,0) -> 0.22100118 | ... L13: =IFERROR((HistoricalFS!L18-HistoricalFS!L24)/HistoricalFS!L6,0) -> 0.21190702 | N13: =IFERROR(AVERAGE(C13:L13),0) -> 0.10558545 | O13: =IFERROR(MEDIAN(C13:L13),0) -> 0.068583197
B14: EBT Margin | C14: =IFERROR(HistoricalFS!C28,0) -> 0 | D14: =IFERROR(HistoricalFS!D28,0) -> -0.033744544 | E14: =IFERROR(HistoricalFS!E28,0) -> -0.046491588 | F14: =IFERROR(HistoricalFS!F28,0) -> -0.028296531 | G14: =IFERROR(HistoricalFS!G28,0) -> -0.033266291 | H14: =IFERROR(HistoricalFS!H28,0) -> 0.020182299 | I14: =IFERROR(HistoricalFS!I28,0) -> 0.15862555 | J14: =IFERROR(HistoricalFS!J28,0) -> 0.20262131 | ... L14: =IFERROR(HistoricalFS!L28,0) -> 0.18842819 | N14: =IFERROR(AVERAGE(C14:L14),0) -> 0.064767468 | O14: =IFERROR(MEDIAN(C14:L14),0) -> 0.01009115
B15: Net Profit Margin | C15: =IFERROR(HistoricalFS!C34,0) -> 0 | D15: =IFERROR(HistoricalFS!D34,0) -> -0.026848893 | E15: =IFERROR(HistoricalFS!E34,0) -> -0.052245927 | F15: =IFERROR(HistoricalFS!F34,0) -> -0.033328997 | G15: =IFERROR(HistoricalFS!G34,0) -> -0.033143537 | H15: =IFERROR(HistoricalFS!H34,0) -> 0.0018764947 | I15: =IFERROR(HistoricalFS!I34,0) -> 0.12457967 | J15: =IFERROR(HistoricalFS!J34,0) -> 0.21134222 | ... L15: =IFERROR(HistoricalFS!L34,0) -> 0.14140651 | N15: =IFERROR(AVERAGE(C15:L15),0) -> 0.049633949 | O15: =IFERROR(MEDIAN(C15:L15),0) -> 0.00093824735
B17: SalesExpenses%Sales | C17: =IFERROR(HistoricalFS!C16,0) -> 0 | D17: =IFERROR(HistoricalFS!D16,0) -> 0.38190964 | E17: =IFERROR(HistoricalFS!E16,0) -> 0.38462117 | F17: =IFERROR(HistoricalFS!F16,0) -> 0.38166905 | G17: =IFERROR(HistoricalFS!G16,0) -> 0.17719989 | H17: =IFERROR(HistoricalFS!H16,0) -> 0.09876351 | I17: =IFERROR(HistoricalFS!I16,0) -> 0.078866375 | J17: =IFERROR(HistoricalFS!J16,0) -> 0.087116995 | ... L17: =IFERROR(HistoricalFS!L16,0) -> 0.10052985 | N17: =IFERROR(AVERAGE(C17:L17),0) -> 0.17842407 | O17: =IFERROR(MEDIAN(C17:L17),0) -> 0.099646678
B18: Depreciation%Sales | C18: =IFERROR(HistoricalFS!C25,0) -> 0 | D18: =IFERROR(HistoricalFS!D25,0) -> 0.059387164 | E18: =IFERROR(HistoricalFS!E25,0) -> 0.054605495 | F18: =IFERROR(HistoricalFS!F25,0) -> 0.060697094 | G18: =IFERROR(HistoricalFS!G25,0) -> 0.043096041 | H18: =IFERROR(HistoricalFS!H25,0) -> 0.069506162 | I18: =IFERROR(HistoricalFS!I25,0) -> 0.056243736 | J18: =IFERROR(HistoricalFS!J25,0) -> 0.050889844 | ... L18: =IFERROR(HistoricalFS!L25,0) -> 0.051137803 | N18: =IFERROR(AVERAGE(C18:L18),0) -> 0.049087949 | O18: =IFERROR(MEDIAN(C18:L18),0) -> 0.052871649
B19: OperatingIncome%Sales | C19: =C13 -> 0 | D19: =D13 -> 0.028235484 | E19: =E13 -> 0.010976618 | F19: =F13 -> 0.031590401 | G19: =G13 -> 0.045333938 | H19: =H13 -> 0.091832457 | I19: =I13 -> 0.18428268 | J19: =J13 -> 0.22100118 | ... L19: =L13 -> 0.21190702 | N19: =IFERROR(AVERAGE(C19:L19),0) -> 0.10558545 | O19: =IFERROR(MEDIAN(C19:L19),0) -> 0.068583197
B21: Return on Capital Employed | C21: =IFERROR((HistoricalFS!C18-HistoricalFS!C24)/(SUM(HistoricalFS!C47:C49)),0) -> 0 | D21: =IFERROR((HistoricalFS!D18-HistoricalFS!D24)/(SUM(HistoricalFS!D47:D49)),0) -> 0.021974672 | E21: =IFERROR((HistoricalFS!E18-HistoricalFS!E24)/(SUM(HistoricalFS!E47:E49)),0) -> 0.0088508368 | F21: =IFERROR((HistoricalFS!F18-HistoricalFS!F24)/(SUM(HistoricalFS!F47:F49)),0) -> 0.027172752 | G21: =IFERROR((HistoricalFS!G18-HistoricalFS!G24)/(SUM(HistoricalFS!G47:G49)),0) -> 0.0140057 | H21: =IFERROR((HistoricalFS!H18-HistoricalFS!H24)/(SUM(HistoricalFS!H47:H49)),0) -> 0.034125657 | I21: =IFERROR((HistoricalFS!I18-HistoricalFS!I24)/(SUM(HistoricalFS!I47:I49)),0) -> 0.10068303 | J21: =IFERROR((HistoricalFS!J18-HistoricalFS!J24)/(SUM(HistoricalFS!J47:J49)),0) -> 0.12450871 | ... L21: =IFERROR((HistoricalFS!L18-HistoricalFS!L24)/(SUM(HistoricalFS!L47:L49)),0) -> 0.12019698 | N21: =IFERROR(AVERAGE(C21:L21),0) -> 0.057999556 | O21: =IFERROR(MEDIAN(C21:L21),0) -> 0.030649205
B22: Retained Earnings% | C22: =IFERROR(HistoricalFS!C44,0) -> 0 | D22: =IFERROR(HistoricalFS!D44,0) -> 0 | E22: =IFERROR(HistoricalFS!E44,0) -> 0 | F22: =IFERROR(HistoricalFS!F44,0) -> 0 | G22: =IFERROR(HistoricalFS!G44,0) -> 0 | H22: =IFERROR(HistoricalFS!H44,0) -> 1 | I22: =IFERROR(HistoricalFS!I44,0) -> 1 | J22: =IFERROR(HistoricalFS!J44,0) -> 0.89931243 | ... L22: =IFERROR(HistoricalFS!L44,0) -> 0.85328061 | N22: =IFERROR(AVERAGE(C22:L22),0) -> 0.45868416 | O22: =IFERROR(MEDIAN(C22:L22),0) -> 0.41712428
B23: Return on Equity% | C23: =IFERROR(HistoricalFS!C33/SUM(HistoricalFS!C47:C48),0) -> 0 | D23: =IFERROR(HistoricalFS!D33/SUM(HistoricalFS!D47:D48),0) -> -0.036213288 | E23: =IFERROR(HistoricalFS!E33/SUM(HistoricalFS!E47:E48),0) -> -0.077617685 | F23: =IFERROR(HistoricalFS!F33/SUM(HistoricalFS!F47:F48),0) -> -0.058513897 | G23: =IFERROR(HistoricalFS!G33/SUM(HistoricalFS!G47:G48),0) -> -0.013747723 | H23: =IFERROR(HistoricalFS!H33/SUM(HistoricalFS!H47:H48),0) -> 0.00083352841 | I23: =IFERROR(HistoricalFS!I33/SUM(HistoricalFS!I47:I48),0) -> 0.077959783 | J23: =IFERROR(HistoricalFS!J33/SUM(HistoricalFS!J47:J48),0) -> 0.1301381 | ... L23: =IFERROR(HistoricalFS!L33/SUM(HistoricalFS!L47:L48),0) -> 0.10594646 | N23: =IFERROR(AVERAGE(C23:L23),0) -> 0.023339463 | O23: =IFERROR(MEDIAN(C23:L23),0) -> 0.00041676421
B24: Self Sustained Growth Rate | C24: =IFERROR(C22*C23,0) -> 0 | D24: =IFERROR(D22*D23,0) -> 0 | E24: =IFERROR(E22*E23,0) -> 0 | F24: =IFERROR(F22*F23,0) -> 0 | G24: =IFERROR(G22*G23,0) -> 0 | H24: =IFERROR(H22*H23,0) -> 0.00083352841 | I24: =IFERROR(I22*I23,0) -> 0.077959783 | J24: =IFERROR(J22*J23,0) -> 0.11703482 | ... L24: =IFERROR(L22*L23,0) -> 0.090402063 | N24: =IFERROR(AVERAGE(C24:L24),0) -> 0.037350038 | O24: =IFERROR(MEDIAN(C24:L24),0) -> 0.00041676421
B25: Interest Coverage Ratio | C25: =((HistoricalFS!C18-HistoricalFS!C24)/HistoricalFS!C21) -> #DIV/0! | D25: =((HistoricalFS!D18-HistoricalFS!D24)/HistoricalFS!D21) -> 0.45555778 | E25: =((HistoricalFS!E18-HistoricalFS!E24)/HistoricalFS!E21) -> 0.19100332 | F25: =((HistoricalFS!F18-HistoricalFS!F24)/HistoricalFS!F21) -> 0.52750074 | G25: =((HistoricalFS!G18-HistoricalFS!G24)/HistoricalFS!G21) -> 0.57676598 | H25: =((HistoricalFS!H18-HistoricalFS!H24)/HistoricalFS!H21) -> 1.2816784 | I25: =((HistoricalFS!I18-HistoricalFS!I24)/HistoricalFS!I21) -> 7.1825121 | J25: =((HistoricalFS!J18-HistoricalFS!J24)/HistoricalFS!J21) -> 12.024088 | ... L25: =((HistoricalFS!L18-HistoricalFS!L24)/HistoricalFS!L21) -> 9.0254515 | N25: =IFERROR(AVERAGE(C25:L25),0) -> 0 | O25: =IFERROR(MEDIAN(C25:L25),0) -> 0
B27: Debtor Turnover Ratio | C27: =HistoricalFS!C6/HistoricalFS!C59 -> #DIV/0! | D27: =HistoricalFS!D6/HistoricalFS!D59 -> 6.8489055 | E27: =HistoricalFS!E6/HistoricalFS!E59 -> 6.1851839 | F27: =HistoricalFS!F6/HistoricalFS!F59 -> 4.6634676 | G27: =HistoricalFS!G6/HistoricalFS!G59 -> 11.02123 | H27: =HistoricalFS!H6/HistoricalFS!H59 -> 6.845418 | I27: =HistoricalFS!I6/HistoricalFS!I59 -> 10.202045 | J27: =HistoricalFS!J6/HistoricalFS!J59 -> 13.574319 | ... L27: =HistoricalFS!L6/HistoricalFS!L59 -> 10.226041 | N27: =IFERROR(AVERAGE(C27:L27),0) -> 0 | O27: =IFERROR(MEDIAN(C27:L27),0) -> 0
B28: Creditor Turnover Ratio | C28: =IFERROR(HistoricalFS!C6/HistoricalFS!C50,0) -> 0 | D28: =IFERROR(HistoricalFS!D6/HistoricalFS!D50,0) -> 1.48964 | E28: =IFERROR(HistoricalFS!E6/HistoricalFS!E50,0) -> 1.4943781 | F28: =IFERROR(HistoricalFS!F6/HistoricalFS!F50,0) -> 1.2177877 | G28: =IFERROR(HistoricalFS!G6/HistoricalFS!G50,0) -> 1.9404328 | H28: =IFERROR(HistoricalFS!H6/HistoricalFS!H50,0) -> 1.388883 | I28: =IFERROR(HistoricalFS!I6/HistoricalFS!I50,0) -> 1.9723571 | J28: =IFERROR(HistoricalFS!J6/HistoricalFS!J50,0) -> 2.2775421 | ... L28: =IFERROR(HistoricalFS!L6/HistoricalFS!L50,0) -> 2.5144029 | N28: =IFERROR(AVERAGE(C28:L28),0) -> 1.6653197 | O28: =IFERROR(MEDIAN(C28:L28),0) -> 1.7174055
B29: Inventory Turnover | C29: =IFERROR(HistoricalFS!C6/HistoricalFS!C60,0) -> 0 | D29: =IFERROR(HistoricalFS!D6/HistoricalFS!D60,0) -> 69.561419 | E29: =IFERROR(HistoricalFS!E6/HistoricalFS!E60,0) -> 61.164839 | F29: =IFERROR(HistoricalFS!F6/HistoricalFS!F60,0) -> 65.014225 | G29: =IFERROR(HistoricalFS!G6/HistoricalFS!G60,0) -> 39.516045 | H29: =IFERROR(HistoricalFS!H6/HistoricalFS!H60,0) -> 46.555204 | I29: =IFERROR(HistoricalFS!I6/HistoricalFS!I60,0) -> 64.072034 | J29: =IFERROR(HistoricalFS!J6/HistoricalFS!J60,0) -> 59.853076 | ... L29: =IFERROR(HistoricalFS!L6/HistoricalFS!L60,0) -> 66.175125 | N29: =IFERROR(AVERAGE(C29:L29),0) -> 53.962264 | O29: =IFERROR(MEDIAN(C29:L29),0) -> 62.618436
B30: Fixed Asset Turnover | C30: =IFERROR(HistoricalFS!C6/HistoricalFS!C53,0) -> 0 | D30: =IFERROR(HistoricalFS!D6/HistoricalFS!D53,0) -> 0.71661676 | E30: =IFERROR(HistoricalFS!E6/HistoricalFS!E53,0) -> 0.7763764 | F30: =IFERROR(HistoricalFS!F6/HistoricalFS!F53,0) -> 0.77132053 | G30: =IFERROR(HistoricalFS!G6/HistoricalFS!G53,0) -> 1.2445267 | H30: =IFERROR(HistoricalFS!H6/HistoricalFS!H53,0) -> 0.38318917 | I30: =IFERROR(HistoricalFS!I6/HistoricalFS!I53,0) -> 0.56023016 | J30: =IFERROR(HistoricalFS!J6/HistoricalFS!J53,0) -> 0.64821629 | ... L30: =IFERROR(HistoricalFS!L6/HistoricalFS!L53,0) -> 0.61108595 | N30: =IFERROR(AVERAGE(C30:L30),0) -> 0.63270231 | O30: =IFERROR(MEDIAN(C30:L30),0) -> 0.63183872
B31: Capital Turnover Ratio | C31: =IFERROR(HistoricalFS!C6/SUM(HistoricalFS!C47:C48),0) -> 0 | D31: =IFERROR(HistoricalFS!D6/SUM(HistoricalFS!D47:D48),0) -> 1.3487814 | E31: =IFERROR(HistoricalFS!E6/SUM(HistoricalFS!E47:E48),0) -> 1.4856217 | F31: =IFERROR(HistoricalFS!F6/SUM(HistoricalFS!F47:F48),0) -> 1.7556453 | G31: =IFERROR(HistoricalFS!G6/SUM(HistoricalFS!G47:G48),0) -> 0.41479349 | H31: =IFERROR(HistoricalFS!H6/SUM(HistoricalFS!H47:H48),0) -> 0.44419439 | I31: =IFERROR(HistoricalFS!I6/SUM(HistoricalFS!I47:I48),0) -> 0.62578253 | J31: =IFERROR(HistoricalFS!J6/SUM(HistoricalFS!J47:J48),0) -> 0.61576956 | ... L31: =IFERROR(HistoricalFS!L6/SUM(HistoricalFS!L47:L48),0) -> 0.74923328 | N31: =IFERROR(AVERAGE(C31:L31),0) -> 0.80827725 | O31: =IFERROR(MEDIAN(C31:L31),0) -> 0.63436665
B33: Debtor Days | C33: =IFERROR(365/C27,0) -> 0 | D33: =IFERROR(365/D27,0) -> 53.293186 | E33: =IFERROR(365/E27,0) -> 59.011989 | F33: =IFERROR(365/F27,0) -> 78.267939 | G33: =IFERROR(365/G27,0) -> 33.1179 | H33: =IFERROR(365/H27,0) -> 53.320338 | I33: =IFERROR(365/I27,0) -> 35.777141 | J33: =IFERROR(365/J27,0) -> 26.889011 | ... L33: =IFERROR(365/L27,0) -> 35.693189 | N33: =IFERROR(AVERAGE(C33:L33),0) -> 40.661028 | O33: =IFERROR(MEDIAN(C33:L33),0) -> 35.735165
B34: Payable Days | C34: =IFERROR(365/C28,0) -> 0 | D34: =IFERROR(365/D28,0) -> 245.02565 | E34: =IFERROR(365/E28,0) -> 244.24876 | F34: =IFERROR(365/F28,0) -> 299.72384 | G34: =IFERROR(365/G28,0) -> 188.10237 | H34: =IFERROR(365/H28,0) -> 262.80111 | I34: =IFERROR(365/I28,0) -> 185.05776 | J34: =IFERROR(365/J28,0) -> 160.26049 | ... L34: =IFERROR(365/L28,0) -> 145.16369 | N34: =IFERROR(AVERAGE(C34:L34),0) -> 188.51908 | O34: =IFERROR(MEDIAN(C34:L34),0) -> 186.58007
B35: Inventory Days | C35: =IFERROR(365/C29,0) -> 0 | D35: =IFERROR(365/D29,0) -> 5.2471615 | E35: =IFERROR(365/E29,0) -> 5.9674808 | F35: =IFERROR(365/F29,0) -> 5.614156 | G35: =IFERROR(365/G29,0) -> 9.2367544 | H35: =IFERROR(365/H29,0) -> 7.8401546 | I35: =IFERROR(365/I29,0) -> 5.6967132 | J35: =IFERROR(365/J29,0) -> 6.0982663 | ... L35: =IFERROR(365/L29,0) -> 5.5156677 | N35: =IFERROR(AVERAGE(C35:L35),0) -> 5.6606938 | O35: =IFERROR(MEDIAN(C35:L35),0) -> 5.6554346
B36: Cash Conversion Cycle (in days) | C36: =SUM(C33,C35)-C34 -> 0 | D36: =SUM(D33,D35)-D34 -> -186.4853 | E36: =SUM(E33,E35)-E34 -> -179.26929 | F36: =SUM(F33,F35)-F34 -> -215.84174 | G36: =SUM(G33,G35)-G34 -> -145.74771 | H36: =SUM(H33,H35)-H34 -> -201.64062 | I36: =SUM(I33,I35)-I34 -> -143.58391 | J36: =SUM(J33,J35)-J34 -> -127.27321 | ... L36: =SUM(L33,L35)-L34 -> -103.95484 | N36: =IFERROR(AVERAGE(C36:L36),0) -> -142.19735 | O36: =IFERROR(MEDIAN(C36:L36),0) -> -144.66581
B38: CFO/Sales | C38: =IFERROR(HistoricalFS!C70/HistoricalFS!C6,0) -> 0 | D38: =IFERROR(HistoricalFS!D70/HistoricalFS!D6,0) -> 0.097036549 | E38: =IFERROR(HistoricalFS!E70/HistoricalFS!E6,0) -> 0.095834321 | F38: =IFERROR(HistoricalFS!F70/HistoricalFS!F6,0) -> 0.052601389 | G38: =IFERROR(HistoricalFS!G70/HistoricalFS!G6,0) -> 0.072793028 | H38: =IFERROR(HistoricalFS!H70/HistoricalFS!H6,0) -> 0.047056099 | I38: =IFERROR(HistoricalFS!I70/HistoricalFS!I6,0) -> 0.19038474 | J38: =IFERROR(HistoricalFS!J70/HistoricalFS!J6,0) -> 0.28144698 | ... L38: =IFERROR(HistoricalFS!L70/HistoricalFS!L6,0) -> 0.2076287 | N38: =IFERROR(AVERAGE(C38:L38),0) -> 0.12522912 | O38: =IFERROR(MEDIAN(C38:L38),0) -> 0.096435435
B39: CFO/Total Assets | C39: =IFERROR(HistoricalFS!C70/HistoricalFS!C64,HistoricalFS!B52) -> 0 | D39: =IFERROR(HistoricalFS!D70/HistoricalFS!D64,HistoricalFS!C52) -> 0.049604272 | E39: =IFERROR(HistoricalFS!E70/HistoricalFS!E64,HistoricalFS!D52) -> 0.050192033 | F39: =IFERROR(HistoricalFS!F70/HistoricalFS!F64,HistoricalFS!E52) -> 0.026516303 | G39: =IFERROR(HistoricalFS!G70/HistoricalFS!G64,HistoricalFS!F52) -> 0.019400251 | H39: =IFERROR(HistoricalFS!H70/HistoricalFS!H64,HistoricalFS!G52) -> 0.013795348 | I39: =IFERROR(HistoricalFS!I70/HistoricalFS!I64,HistoricalFS!H52) -> 0.081453848 | J39: =IFERROR(HistoricalFS!J70/HistoricalFS!J64,HistoricalFS!I52) -> 0.1271183 | ... L39: =IFERROR(HistoricalFS!L70/HistoricalFS!L64,HistoricalFS!K52) -> 0.096092962 | N39: =IFERROR(AVERAGE(C39:L39),0) -> 0.055765712 | O39: =IFERROR(MEDIAN(C39:L39),0) -> 0.049898152
B40: CFO/Total Debt | C40: =IFERROR(HistoricalFS!C70/HistoricalFS!C49,0) -> 0 | D40: =IFERROR(HistoricalFS!D70/HistoricalFS!D49,0) -> 0.17853997 | E40: =IFERROR(HistoricalFS!E70/HistoricalFS!E49,0) -> 0.16900216 | F40: =IFERROR(HistoricalFS!F70/HistoricalFS!F49,0) -> 0.088706058 | G40: =IFERROR(HistoricalFS!G70/HistoricalFS!G49,0) -> 0.088129044 | H40: =IFERROR(HistoricalFS!H70/HistoricalFS!H49,0) -> 0.10700829 | I40: =IFERROR(HistoricalFS!I70/HistoricalFS!I49,0) -> 0.81947273 | J40: =IFERROR(HistoricalFS!J70/HistoricalFS!J49,0) -> 1.8638673 | ... L40: =IFERROR(HistoricalFS!L70/HistoricalFS!L49,0) -> 0.48477389 | N40: =IFERROR(AVERAGE(C40:L40),0) -> 0.466312 | O40: =IFERROR(MEDIAN(C40:L40),0) -> 0.17377106

Sheet Forecasting
B2: ='Data Sheet'!$B$1&" - "&'Data Sheet'!A17&" Forecasting" -> MAX HEALTHCARE INSTITUTE LTD - Sales Forecasting | G2: ='Data Sheet'!$B$1&" - "&'Data Sheet'!A34&" Forecasting" -> MAX HEALTHCARE INSTITUTE LTD - EBITDA Forecasting | L2: ='Data Sheet'!$B$1&" - "&HistoricalFS!B38&" Forecasting" -> MAX HEALTHCARE INSTITUTE LTD - Earnings per Share Forecasting
B3: Year Weight | C3: Year | D3: Sales | E3: Sales Growth | G3: Year Weight | H3: Year | I3: EBITDA | J3: EBITDA Growth | L3: Year Weight | M3: Year | N3: EBITDA | O3: EBITDA Growth
B4: 1 | C4: ='Data Sheet'!$B$16 -> 41729 | D4: {=TRANSPOSE('Data Sheet'!B17:K17)} -> 0 | G4: 1 | H4: ='Data Sheet'!$B$16 -> 41729 | I4: {=TRANSPOSE('Data Sheet'!B34:K34)} -> 0 | L4: 1 | M4: ='Data Sheet'!$B$16 -> 41729 | N4: {=TRANSPOSE(HistoricalFS!C38:L38)} -> 0
B5: =B4+1 -> 2 | C5: =C4+365 -> 42094 | D5: 1608.26 | E5: =D5/D4-1 -> #DIV/0! | G5: =G4+1 -> 2 | H5: =H4+365 -> 42094 | I5: 199.89 | J5: =I5/I4-1 -> #DIV/0! | L5: =L4+1 -> 2 | M5: =M4+365 -> 42094 | N5: -0.80379747 | O5: =N5/N4-1 -> #DIV/0!
B6: =B5+1 -> 3 | C6: =C5+365 -> 42459 | D6: 1729.13 | E6: =D6/D5-1 -> 0.075155758 | G6: =G5+1 -> 3 | H6: =H5+365 -> 42459 | I6: 178.59 | J6: =I6/I5-1 -> -0.10655861 | L6: =L5+1 -> 3 | M6: =M5+365 -> 42459 | N6: -1.6816828 | O6: =N6/N5-1 -> 1.0921723
B7: =B6+1 -> 4 | C7: =C6+365 -> 42824 | D7: 1691.02 | E7: =D7/D6-1 -> -0.022039985 | G7: =G6+1 -> 4 | H7: =H6+365 -> 42824 | I7: 209.41 | J7: =I7/I6-1 -> 0.17257405 | L7: =L6+1 -> 4 | M7: =M6+365 -> 42824 | N7: -1.0491437 | O7: =N7/N6-1 -> -0.3761346
B8: =B7+1 -> 5 | C8: =C7+365 -> 43189 | D8: 1059.03 | E8: =D8/D7-1 -> -0.37373301 | G8: =G7+1 -> 5 | H8: =H7+365 -> 43189 | I8: 187.74 | J8: =I8/I7-1 -> -0.10348121 | L8: =L7+1 -> 5 | M8: =M7+365 -> 43189 | N8: -0.65338794 | O8: =N8/N7-1 -> -0.37721789
B9: =B8+1 -> 6 | C9: =C8+365 -> 43554 | D9: 2504.67 | E9: =D9/D8-1 -> 1.3650605 | G9: =G8+1 -> 6 | H9: =H8+365 -> 43554 | I9: 261.85 | J9: =I9/I8-1 -> 0.39474806 | L9: =L8+1 -> 6 | M9: =M8+365 -> 43554 | N9: 0.048659281 | O9: =N9/N8-1 -> -1.0744723
B10: =B9+1 -> 7 | C10: =C9+365 -> 43919 | D10: 3931.46 | E10: =D10/D9-1 -> 0.56965189 | G10: =G9+1 -> 7 | H10: =H9+365 -> 43919 | I10: 1060.89 | J10: =I10/I9-1 -> 3.051518 | L10: =L9+1 -> 7 | M10: =M9+365 -> 43919 | N10: 5.0513614 | O10: =N10/N9-1 -> 102.81085
B11: =B10+1 -> 8 | C11: =C10+365 -> 44284 | D11: 4562.6 | E11: =D11/D10-1 -> 0.16053578 | G11: =G10+1 -> 8 | H11: =H10+365 -> 44284 | I11: 1379.77 | J11: =I11/I10-1 -> 0.30057782 | L11: =L10+1 -> 8 | M11: =M10+365 -> 44284 | N11: 9.9317128 | O11: =N11/N10-1 -> 0.96614577
B12: =B11+1 -> 9 | C12: =C11+365 -> 44649 | D12: 5406.02 | E12: =D12/D11-1 -> 0.18485513 | G12: =G11+1 -> 9 | H12: =H11+365 -> 44649 | I12: 1670.19 | J12: =I12/I11-1 -> 0.21048436 | L12: =L11+1 -> 9 | M12: =M11+365 -> 44649 | N12: 9.0500051 | O12: =N12/N11-1 -> -0.088777003
B13: =B12+1 -> 10 | C13: =C12+365 -> 45014 | D13: 7028.46 | E13: =D13/D12-1 -> 0.30011728 | G13: =G12+1 -> 10 | H13: =H12+365 -> 45014 | I13: 1930.81 | J13: =I13/I12-1 -> 0.15604213 | L13: =L12+1 -> 10 | M13: =M12+365 -> 45014 | N13: 10.223948 | O13: =N13/N12-1 -> 0.12971739
B14: =B13+1 -> 11 | C14: =C13+365 -> 45379 | D14: =FORECAST(B14,$D$4:$D$13,$B$4:$B$13) -> 6691.224 | E14: =D14/D13-1 -> -0.047981492 | G14: =G13+1 -> 11 | H14: =H13+365 -> 45379 | I14: =FORECAST(G14,$I$4:$I$13,$G$4:$G$13) -> 1918.042 | J14: =I14/I13-1 -> -0.0066127687 | L14: =L13+1 -> 11 | M14: =M13+365 -> 45379 | N14: =FORECAST(L14,$N$4:$N$13,$L$4:$L$13) -> 10.947191 | O14: =N14/N13-1 -> 0.070740032
B15: =B14+1 -> 12 | C15: =C14+365 -> 45744 | D15: =FORECAST(B15,$D$4:$D$13,$B$4:$B$13) -> 7371.0711 | E15: =D15/D14-1 -> 0.1016028 | G15: =G14+1 -> 12 | H15: =H14+365 -> 45744 | I15: =FORECAST(G15,$I$4:$I$13,$G$4:$G$13) -> 2138.0653 | J15: =I15/I14-1 -> 0.11471244 | L15: =L14+1 -> 12 | M15: =M14+365 -> 45744 | N15: =FORECAST(L15,$N$4:$N$13,$L$4:$L$13) -> 12.389995 | O15: =N15/N14-1 -> 0.13179676
B16: =B15+1 -> 13 | C16: =C15+365 -> 46109 | D16: =FORECAST(B16,$D$4:$D$13,$B$4:$B$13) -> 8050.9182 | E16: =D16/D15-1 -> 0.092231791 | G16: =G15+1 -> 13 | H16: =H15+365 -> 46109 | I16: =FORECAST(G16,$I$4:$I$13,$G$4:$G$13) -> 2358.0885 | J16: =I16/I15-1 -> 0.10290765 | L16: =L15+1 -> 13 | M16: =M15+365 -> 46109 | N16: =FORECAST(L16,$N$4:$N$13,$L$4:$L$13) -> 13.832799 | O16: =N16/N15-1 -> 0.11644914
B17: =B16+1 -> 14 | C17: =C16+365 -> 46474 | D17: =FORECAST(B17,$D$4:$D$13,$B$4:$B$13) -> 8730.7653 | E17: =D17/D16-1 -> 0.084443423 | G17: =G16+1 -> 14 | H17: =H16+365 -> 46474 | I17: =FORECAST(G17,$I$4:$I$13,$G$4:$G$13) -> 2578.1118 | J17: =I17/I16-1 -> 0.093305772 | L17: =L16+1 -> 14 | M17: =M16+365 -> 46474 | N17: =FORECAST(L17,$N$4:$N$13,$L$4:$L$13) -> 15.275603 | O17: =N17/N16-1 -> 0.10430313
B18: =B17+1 -> 15 | C18: =C17+365 -> 46839 | D18: =FORECAST(B18,$D$4:$D$13,$B$4:$B$13) -> 9410.6124 | E18: =D18/D17-1 -> 0.077867984 | G18: =G17+1 -> 15 | H18: =H17+365 -> 46839 | I18: =FORECAST(G18,$I$4:$I$13,$G$4:$G$13) -> 2798.1351 | J18: =I18/I17-1 -> 0.085342797 | L18: =L17+1 -> 15 | M18: =M17+365 -> 46839 | N18: =FORECAST(L18,$N$4:$N$13,$L$4:$L$13) -> 16.718407 | O18: =N18/N17-1 -> 0.094451537

Sheet Data Sheet
A1: COMPANY NAME | B1: MAX HEALTHCARE INSTITUTE LTD | E1: =IF(B2<>B3, "A NEW VERSION OF THE WORKSHEET IS AVAILABLE", "")
A2: LATEST VERSION | B2: 2.1 | E2: PLEASE DO NOT MAKE ANY CHANGES TO THIS SHEET
A3: CURRENT VERSION | B3: 2.1
A5: META
A6: Number of shares | B6: =IF(B9>0, B9/B8, 0) -> 97.327409
A7: Face Value | B7: 10
A8: Current Price | B8: 1117.5
A9: Market Capitalization | B9: 108763.38
A15: PROFIT & LOSS | B15: =B26+B34 -> 0 | K15: =K17-K18-K20-K21-K22-K23-K19 -> 1936.18
A16: Report Date | B16: 41729 | C16: 42825 | D16: 43190 | E16: 43555 | F16: 43921 | G16: 44286 | H16: 44651 | I16: 45016 | J16: 45382 | K16: 45747
A17: Sales | C17: 1608.26 | D17: 1729.13 | E17: 1691.02 | F17: 1059.03 | G17: 2504.67 | H17: 3931.46 | I17: 4562.6 | J17: 5406.02 | K17: 7028.46
A18: Raw Material Cost | C18: 423 | D18: 431.05 | E18: 362.2 | F18: 229.35 | G18: 580.51 | H18: 930.46 | I18: 936.88 | J18: 1119.04 | K18: 1496.41
A19: Change in Inventory | C19: -0.1 | D19: 5.15 | E19: -2.26 | I19: 14.87 | J19: 0.52 | K19: 19.36
A20: Power and Fuel | C20: 40.9 | D20: 41.36 | E20: 46.06 | F20: 22.72 | G20: 51.37 | H20: 62.67 | I20: 69.04 | J20: 77.54 | K20: 115.03
A21: Other Mfr. Exp | C21: 35.04 | D21: 59.86 | E21: 37.88 | F21: 295.52 | G21: 631.68 | H21: 921.31 | I21: 1120.86 | J21: 1271.08 | K21: 1696.97
A22: Employee Cost | C22: 354.09 | D22: 423.55 | E22: 441.15 | F22: 230.13 | G22: 589.64 | H22: 761.34 | I22: 812.68 | J22: 940.95 | K22: 1184.04
A23: Selling and admin | C23: 593.33 | D23: 647.35 | E23: 629.63 | F23: 153 | G23: 208 | H23: 290 | I23: 628.69 | J23: 737.66 | K23: 580.47
A24: Other Expenses | C24: 20.88 | D24: 17.71 | E24: 15.78 | F24: 34.66 | G24: 39.37 | H24: 20.06 | I24: -231.21 | J24: -231.85 | K24: 126.1
A25: Other Income | C25: 58.97 | D25: 65.19 | E25: 56.17 | F25: 48.01 | G25: -119.2 | H25: 115.27 | I25: 139.24 | J25: 178.07 | K25: 82.01
A26: Depreciation | C26: 95.51 | D26: 94.42 | E26: 102.64 | F26: 45.64 | G26: 174.09 | H26: 221.12 | I26: 232.19 | J26: 244.98 | K26: 359.42
A27: Interest | C27: 99.68 | D27: 99.37 | E27: 101.27 | F27: 83.24 | G27: 179.46 | H27: 100.87 | I27: 83.86 | J27: 59.89 | K27: 165.02
A28: Profit before tax | C28: 4.7 | D28: -15.2 | E28: 8.32 | F28: 12.78 | G28: -68.65 | H28: 738.9 | I28: 1063.72 | J28: 1365.32 | K28: 1406.37
A29: Tax | C29: -11.09 | D29: 9.95 | E29: 8.51 | F29: -0.13 | G29: 45.85 | H29: 133.85 | I29: -39.79 | J29: 307.68 | K29: 330.49
A30: Net profit | C30: 15.79 | D30: -25.15 | E30: -3.01 | F30: 58.99 | G30: -137.55 | H30: 605.05 | I30: 1103.51 | J30: 1057.64 | K30: 1075.88
A31: Dividend Amount | I31: 97.09 | J31: 145.79 | K31: 145.82
A32: Effective Tax Rate | B32: =B29/B28 -> #DIV/0! | C32: =C29/C28 -> -2.3595745 | D32: =D29/D28 -> -0.65460526 | E32: =E29/E28 -> 1.0228365 | F32: =F29/F28 -> -0.010172144 | G32: =G29/G28 -> -0.66788055 | H32: =H29/H28 -> 0.18114765 | I32: =I29/I28 -> -0.03740646 | ... K32: =K29/K28 -> 0.23499506
A34: EBITDA | B34: =+B30+B29+B27+B26 -> 0 | C34: =+C30+C29+C27+C26 -> 199.89 | D34: =+D30+D29+D27+D26 -> 178.59 | E34: =+E30+E29+E27+E26 -> 209.41 | F34: =+F30+F29+F27+F26 -> 187.74 | G34: =+G30+G29+G27+G26 -> 261.85 | H34: =+H30+H29+H27+H26 -> 1060.89 | I34: =+I30+I29+I27+I26 -> 1379.77 | ... K34: =+K30+K29+K27+K26 -> 1930.81
A40: Quarters
A41: Report Date | B41: 45107 | C41: 45199 | D41: 45291 | E41: 45382 | F41: 45473 | G41: 45565 | H41: 45657 | I41: 45747 | J41: 45838 | K41: 45930
A42: Sales | B42: 1284.99 | C42: 1363.16 | D42: 1334.97 | E42: 1422.9 | F42: 1542.95 | G42: 1707.46 | H42: 1868.31 | I42: 1909.74 | J42: 2027.57 | K42: 2135.47
A43: Expenses | B43: 947.61 | C43: 975.81 | D43: 949.11 | E43: 1041.37 | F43: 1155.54 | G43: 1256.92 | H43: 1369.18 | I43: 1398.12 | J43: 1504.66 | K43: 1560.32
A44: Other Income | B44: 41.32 | C44: 45.48 | D44: 46.02 | E44: 45.25 | F44: 34.68 | G44: 40.84 | H44: -40.33 | I44: 46.92 | J44: 36.51 | K44: 32.9
A45: Depreciation | B45: 55.82 | C45: 57.88 | D45: 60.96 | E45: 70.32 | F45: 76.9 | G45: 84.15 | H45: 97.54 | I45: 100.83 | J45: 104.14 | K45: 108.1
A46: Interest | B46: 19.39 | C46: 8.53 | D46: 11.24 | E46: 20.73 | F46: 23.88 | G46: 33.54 | H46: 52.39 | I46: 55.21 | J46: 54.85 | K46: 53.92
A47: Profit before tax | B47: 303.49 | C47: 366.42 | D47: 359.68 | E47: 335.73 | F47: 321.31 | G47: 373.69 | H47: 308.87 | I47: 402.5 | J47: 400.43 | K47: 446.03
A48: Tax | B48: 63.41 | C48: 89.74 | D48: 70.34 | E48: 84.19 | F48: 85.04 | G48: 91.88 | H48: 70.07 | I48: 83.5 | J48: 92.46 | K48: -45.27
A49: Net profit | B49: 240.08 | C49: 276.68 | D49: 289.34 | E49: 251.54 | F49: 236.27 | G49: 281.81 | H49: 238.8 | I49: 319 | J49: 307.97 | K49: 491.3
A50: Operating Profit | B50: 337.38 | C50: 387.35 | D50: 385.86 | E50: 381.53 | F50: 387.41 | G50: 450.54 | H50: 499.13 | I50: 511.62 | J50: 522.91 | K50: 575.15
A51: EBITDA | B51: =B49+B48+B46+B45 -> 378.7 | C51: =C49+C48+C46+C45 -> 432.83 | D51: =D49+D48+D46+D45 -> 431.88 | E51: =E49+E48+E46+E45 -> 426.78 | F51: =F49+F48+F46+F45 -> 422.09 | G51: =G49+G48+G46+G45 -> 491.38 | H51: =H49+H48+H46+H45 -> 458.8 | I51: =I49+I48+I46+I45 -> 558.54 | ... K51: =K49+K48+K46+K45 -> 608.05
A55: BALANCE SHEET
...
